<sdf version='1.6'>
  <model name='iCubHeidelberg01_SIM_MODEL'>
    <link name='root_link'>
      <pose frame=''>0 0 0 0 -0 0</pose>
      <inertial>
        <pose frame=''>0.025114 0.000104 -0.043745 0 -0 0</pose>
        <mass>5.1504</mass>
        <inertia>
          <ixx>0.0252712</ixx>
          <ixy>-8.71849e-05</ixy>
          <ixz>0.00172034</ixz>
          <iyy>0.0140911</iyy>
          <iyz>-6.63933e-05</iyz>
          <izz>0.0205529</izz>
        </inertia>
      </inertial>
      <collision name='root_link_collision'>
        <pose frame=''>-0.0364 0 0.032 1.5708 0 -1.5708</pose>
        <geometry>
          <mesh>
            <scale>0.001 0.001 0.001</scale>
            <uri>model://heicub/meshes/sim_root_link_prt.dae</uri>
          </mesh>
        </geometry>
      </collision>
      <visual name='root_link_visual'>
        <pose frame=''>-0.0364 0 0.032 1.5708 0 -1.5708</pose>
        <geometry>
          <mesh>
            <scale>0.001 0.001 0.001</scale>
            <uri>model://heicub/meshes/sim_root_link_prt.dae</uri>
          </mesh>
        </geometry>
      </visual>
    </link>
    <link name='l_hip_1'>
      <pose frame=''>0.006452 -0.0111 -0.119913 1.57752 -0 1.5708</pose>
      <inertial>
        <pose frame=''>-0.052968 -3.6e-05 0.000539 0 -0 0</pose>
        <mass>0.9279</mass>
        <inertia>
          <ixx>0.000403391</ixx>
          <ixy>-1.46807e-06</ixy>
          <ixz>-2.86703e-06</ixz>
          <iyy>0.00057246</iyy>
          <iyz>2.05247e-07</iyz>
          <izz>0.000577587</izz>
        </inertia>
      </inertial>
      <collision name='l_hip_1_collision'>
        <pose frame=''>0.0111 0.151913 -0.042852 0 -0 0</pose>
        <geometry>
          <mesh>
            <scale>0.001 0.001 0.001</scale>
            <uri>model://heicub/meshes/sim_sea_l_hip_1_prt.dae</uri>
          </mesh>
        </geometry>
      </collision>
      <visual name='l_hip_1_visual'>
        <pose frame=''>0.0111 0.151913 -0.042852 0 -0 0</pose>
        <geometry>
          <mesh>
            <scale>0.001 0.001 0.001</scale>
            <uri>model://heicub/meshes/sim_sea_l_hip_1_prt.dae</uri>
          </mesh>
        </geometry>
      </visual>
    </link>
    <joint name='l_hip_pitch' type='revolute'>
      <child>l_hip_1</child>
      <parent>root_link</parent>
      <axis>
        <xyz>0 1 0</xyz>
        <limit>
          <lower>-0.57</lower>
          <upper>1.74</upper>
          <effort>50000</effort>
          <velocity>50000</velocity>
        </limit>
        <dynamics>
          <damping>0.223</damping>
          <friction>0</friction>
          <spring_reference>0</spring_reference>
          <spring_stiffness>0</spring_stiffness>
        </dynamics>
        <use_parent_model_frame>1</use_parent_model_frame>
      </axis>
    </joint>
    <link name='l_hip_2'>
      <pose frame=''>0.032813 -0.0701 -0.120091 1.57752 -0 1.5708</pose>
      <inertial>
        <pose frame=''>4e-06 -0.044267 -0.024686 0 -0 0</pose>
        <mass>0.4184</mass>
        <inertia>
          <ixx>0.000487899</ixx>
          <ixy>-2.36572e-07</ixy>
          <ixz>-1.91626e-07</ixz>
          <iyy>0.000285982</iyy>
          <iyz>-1.21736e-05</iyz>
          <izz>0.000315299</izz>
        </inertia>
      </inertial>
      <collision name='l_hip_2_collision'>
        <pose frame=''>0.0701 0.151914 -0.069214 0 -0 0</pose>
        <geometry>
          <mesh>
            <scale>0.001 0.001 0.001</scale>
            <uri>model://heicub/meshes/sim_sea_l_hip_2_prt.dae</uri>
          </mesh>
        </geometry>
      </collision>
      <visual name='l_hip_2_visual'>
        <pose frame=''>0.0701 0.151914 -0.069214 0 -0 0</pose>
        <geometry>
          <mesh>
            <scale>0.001 0.001 0.001</scale>
            <uri>model://heicub/meshes/sim_sea_l_hip_2_prt.dae</uri>
          </mesh>
        </geometry>
      </visual>
    </link>
    <joint name='l_hip_roll' type='revolute'>
      <child>l_hip_2</child>
      <parent>l_hip_1</parent>
      <axis>
        <xyz>-1 0 -0</xyz>
        <limit>
          <lower>-0.33</lower>
          <upper>1.5708</upper>
          <effort>50000</effort>
          <velocity>50000</velocity>
        </limit>
        <dynamics>
          <damping>0.223</damping>
          <friction>0</friction>
          <spring_reference>0</spring_reference>
          <spring_stiffness>0</spring_stiffness>
        </dynamics>
        <use_parent_model_frame>1</use_parent_model_frame>
      </axis>
    </joint>
    <link name='l_hip_3'>
      <pose frame=''>0.00681 -0.0701 -0.194218 3.14159 -0 3.14159</pose>
      <inertial>
        <pose frame=''>-0.000622 0.000282 0.008713 0 -0 0</pose>
        <mass>0.1262</mass>
        <inertia>
          <ixx>3.33523e-05</ixx>
          <ixy>-4.04554e-08</ixy>
          <ixz>8.80407e-08</ixz>
          <iyy>3.34665e-05</iyy>
          <iyz>-7.47286e-08</iyz>
          <izz>5.70757e-05</izz>
        </inertia>
      </inertial>
      <collision name='l_hip_3_collision'>
        <pose frame=''>0.042188 0.0701 -0.226503 -1.56408 0 1.5708</pose>
        <geometry>
          <mesh>
            <scale>0.001 0.001 0.001</scale>
            <uri>model://heicub/meshes/sim_sea_l_upper_thigh_prt.dae</uri>
          </mesh>
        </geometry>
      </collision>
      <visual name='l_hip_3_visual'>
        <pose frame=''>0.042188 0.0701 -0.226503 -1.56408 0 1.5708</pose>
        <geometry>
          <mesh>
            <scale>0.001 0.001 0.001</scale>
            <uri>model://heicub/meshes/sim_sea_l_upper_thigh_prt.dae</uri>
          </mesh>
        </geometry>
      </visual>
    </link>
    <joint name='l_leg_ft_sensor' type='revolute'>
      <child>l_hip_3</child>
      <parent>l_hip_2</parent>
      <axis>
        <limit>
          <lower>0</lower>
          <upper>0</upper>
        </limit>
        <dynamics>
          <damping>0</damping>
          <friction>0</friction>
          <spring_reference>0</spring_reference>
          <spring_stiffness>0</spring_stiffness>
        </dynamics>
        <use_parent_model_frame>1</use_parent_model_frame>
        <xyz>0 0 1</xyz>
      </axis>
      <physics>
        <ode>
          <limit>
            <cfm>0</cfm>
            <erp>0.2</erp>
          </limit>
        </ode>
      </physics>
      <sensor name='l_leg_ft_sensor' type='force_torque'>
        <always_on>1</always_on>
        <update_rate>100</update_rate>
        <force_torque>
          <frame>child</frame>
          <measure_direction>child_to_parent</measure_direction>
        </force_torque>
        <pose>0 0 0 0 0 0</pose>
        <plugin name='left_leg_ft_plugin' filename='libgazebo_yarp_forcetorque.so'>
          <yarpConfigurationFile>model://heicub/conf/FT/gazebo_iCubHeidelberg01_left_leg_ft.ini</yarpConfigurationFile>
        </plugin>
      </sensor>
    </joint>
    <link name='l_upper_leg'>
      <pose frame=''>0.006689 -0.0701 -0.212217 1.57752 -0 1.5708</pose>
      <inertial>
        <pose frame=''>-5.9e-05 -0.079158 -0.002149 0 -0 0</pose>
        <mass>2.2544</mass>
        <inertia>
          <ixx>0.00794621</ixx>
          <ixy>0.000169715</ixy>
          <ixz>-1.07286e-05</ixz>
          <iyy>0.00179482</iyy>
          <iyz>0.000204937</iyz>
          <izz>0.0079671</izz>
        </inertia>
      </inertial>
      <collision name='l_upper_leg_collision'>
        <pose frame=''>0.0701 0.241013 -0.043709 0 -0 0</pose>
        <geometry>
          <mesh>
            <scale>0.001 0.001 0.001</scale>
            <uri>model://heicub/meshes/sim_sea_l_thigh_prt.dae</uri>
          </mesh>
        </geometry>
      </collision>
      <visual name='l_upper_leg_visual'>
        <pose frame=''>0.0701 0.241013 -0.043709 0 -0 0</pose>
        <geometry>
          <mesh>
            <scale>0.001 0.001 0.001</scale>
            <uri>model://heicub/meshes/sim_sea_l_thigh_prt.dae</uri>
          </mesh>
        </geometry>
      </visual>
    </link>
    <joint name='l_hip_yaw' type='revolute'>
      <child>l_upper_leg</child>
      <parent>l_hip_3</parent>
      <axis>
        <xyz>-0 -0 1</xyz>
        <limit>
          <lower>-1.309</lower>
          <upper>1.309</upper>
          <effort>50000</effort>
          <velocity>50000</velocity>
        </limit>
        <dynamics>
          <damping>0.223</damping>
          <friction>0</friction>
          <spring_reference>0</spring_reference>
          <spring_stiffness>0</spring_stiffness>
        </dynamics>
        <use_parent_model_frame>1</use_parent_model_frame>
      </axis>
    </joint>
    <link name='l_lower_leg'>
      <pose frame=''>0.00571 -0.088057 -0.357839 1.57752 -0 1.5708</pose>
      <inertial>
        <pose frame=''>0.011764 -0.083361 -0.000293 0 -0 0</pose>
        <mass>1.7086</mass>
        <inertia>
          <ixx>0.00565145</ixx>
          <ixy>0.000651871</ixy>
          <ixz>-1.78506e-05</ixz>
          <iyy>0.00171182</iyy>
          <iyz>0.000177424</iyz>
          <izz>0.00615194</izz>
        </inertia>
      </inertial>
      <collision name='l_lower_leg_collision'>
        <pose frame=''>0.084257 0.386639 -0.043709 0 -0 0</pose>
        <geometry>
          <mesh>
            <scale>0.001 0.001 0.001</scale>
            <uri>model://heicub/meshes/sim_sea_l_shank_prt.dae</uri>
          </mesh>
        </geometry>
      </collision>
      <visual name='l_lower_leg_visual'>
        <pose frame=''>0.084257 0.386639 -0.043709 0 -0 0</pose>
        <geometry>
          <mesh>
            <scale>0.001 0.001 0.001</scale>
            <uri>model://heicub/meshes/sim_sea_l_shank_prt.dae</uri>
          </mesh>
        </geometry>
      </visual>
    </link>
    <joint name='l_knee' type='revolute'>
      <child>l_lower_leg</child>
      <parent>l_upper_leg</parent>
      <axis>
        <xyz>0 1 0</xyz>
        <limit>
          <lower>-1.74533</lower>
          <upper>0</upper>
          <effort>50000</effort>
          <velocity>50000</velocity>
        </limit>
        <dynamics>
          <damping>0.223</damping>
          <friction>0</friction>
          <spring_reference>0</spring_reference>
          <spring_stiffness>0</spring_stiffness>
        </dynamics>
        <use_parent_model_frame>1</use_parent_model_frame>
      </axis>
    </joint>
    <link name='l_ankle_1'>
      <pose frame=''>0.007309 -0.1094 -0.558838 1.57754 -0 1.5708</pose>
      <inertial>
        <pose frame=''>0.034639 -0.000149 -0.015161 0 -0 0</pose>
        <mass>0.8929</mass>
        <inertia>
          <ixx>0.000539928</ixx>
          <ixy>-3.69491e-07</ixy>
          <ixz>3.92722e-05</ixz>
          <iyy>0.000581685</iyy>
          <iyz>-2.38798e-06</iyz>
          <izz>0.000414659</izz>
        </inertia>
      </inertial>
      <collision name='l_ankle_1_collision'>
        <pose frame=''>0.1056 0.587122 -0.046658 0 -0 0</pose>
        <geometry>
          <mesh>
            <scale>0.001 0.001 0.001</scale>
            <uri>model://heicub/meshes/sim_sea_l_ankle_prt.dae</uri>
          </mesh>
        </geometry>
      </collision>
      <visual name='l_ankle_1_visual'>
        <pose frame=''>0.1056 0.587122 -0.046658 0 -0 0</pose>
        <geometry>
          <mesh>
            <scale>0.001 0.001 0.001</scale>
            <uri>model://heicub/meshes/sim_sea_l_ankle_prt.dae</uri>
          </mesh>
        </geometry>
      </visual>
    </link>
    <joint name='l_ankle_pitch' type='revolute'>
      <child>l_ankle_1</child>
      <parent>l_lower_leg</parent>
      <axis>
        <xyz>-0 -1 -0</xyz>
        <limit>
          <lower>-0.62</lower>
          <upper>0.47</upper>
          <effort>50000</effort>
          <velocity>50000</velocity>
        </limit>
        <dynamics>
          <damping>0.223</damping>
          <friction>0</friction>
          <spring_reference>0</spring_reference>
          <spring_stiffness>0</spring_stiffness>
        </dynamics>
        <use_parent_model_frame>1</use_parent_model_frame>
      </axis>
    </joint>
    <link name='l_ankle_2'>
      <pose frame=''>-0.040202 -0.0739 -0.558534 1.57754 -0 1.5708</pose>
      <inertial>
        <pose frame=''>-8e-06 -0.03819 0.047001 0 -0 0</pose>
        <mass>0.2675</mass>
        <inertia>
          <ixx>0.000329604</ixx>
          <ixy>6.02297e-07</ixy>
          <ixz>-7.99854e-08</ixz>
          <iyy>0.00025376</iyy>
          <iyz>-6.95068e-07</iyz>
          <izz>0.000148713</izz>
        </inertia>
      </inertial>
<!--
      <collision name='l_ankle_2_collision'>
        <pose frame=''>0.0701 0.587139 0.000853 0 -0 0</pose>
        <geometry>
          <mesh>
            <scale>0.001 0.001 0.001</scale>
            <uri>model://heicub/meshes/sim_sea_l_foot_prt.dae</uri>
          </mesh>
        </geometry>
      </collision>
-->
      <visual name='l_ankle_2_visual'>
        <pose frame=''>0.0701 0.587139 0.000853 0 -0 0</pose>
        <geometry>
          <mesh>
            <scale>0.001 0.001 0.001</scale>
            <uri>model://heicub/meshes/sim_sea_l_foot_prt.dae</uri>
          </mesh>
        </geometry>
      </visual>
    </link>
    <joint name='l_ankle_roll' type='revolute'>
      <child>l_ankle_2</child>
      <parent>l_ankle_1</parent>
      <axis>
        <xyz>-1 0 -0</xyz>
        <limit>
          <lower>-0.418</lower>
          <upper>0.418</upper>
          <effort>50000</effort>
          <velocity>50000</velocity>
        </limit>
        <dynamics>
          <damping>0.223</damping>
          <friction>0</friction>
          <spring_reference>0</spring_reference>
          <spring_stiffness>0</spring_stiffness>
        </dynamics>
        <use_parent_model_frame>1</use_parent_model_frame>
      </axis>
    </joint>
    <link name='l_foot'>
      <pose frame=''>0.007453 -0.0739 -0.619157 3.14159 -0 3.14159</pose>
      <inertial>
        <pose frame=''>0.030528 -0.005405 -0.001173 0 -0 0</pose>
        <mass>0.3794</mass>
        <inertia>
          <ixx>0.000283689</ixx>
          <ixy>-5.83552e-05</ixy>
          <ixz>7.87665e-06</ixz>
          <iyy>0.00121493</iyy>
          <iyz>8.91516e-07</iyz>
          <izz>0.00140898</izz>
        </inertia>
      </inertial>
<!--
      <collision name='l_foot_collision'>
        <pose frame=''>0.042842 0.0701 -0.647743 -1.56405 -0 1.5708</pose>
        <geometry>
          <mesh>
            <scale>0.001 0.001 0.001</scale>
            <uri>model://heicub/meshes/sim_sea_l_sole_prt.dae</uri>
          </mesh>
        </geometry>
      </collision>
-->
      <collision name='l_foot_collision_simplified'>
        <pose>0.03 -0.0 -0.006 0.0 0.0 0.0</pose>
        <geometry>
          <box>
            <size>0.22 0.10 0.04</size>
          </box>
        </geometry>
        <max_contacts>4</max_contacts>
        <surface>
          <contact>
            <ode>
              <soft_erp>0.2</soft_erp>
              <soft_cfm>0</soft_cfm>
              <kp>180000</kp>
              <kd>100</kd>
              <max_vel>100</max_vel>
              <min_depth>0.0001</min_depth>
            </ode>
          </contact>
          <friction>
            <ode>
              <mu>1</mu>
              <mu2>1</mu2>
              <fdir1>0 0 0</fdir1>
              <slip1>0</slip1>
              <slip2>0</slip2>
            </ode>
          </friction>
          <bounce>
            <restitution_coefficient>0</restitution_coefficient>
            <threshold>100000</threshold>
          </bounce>
        </surface>
      </collision>
      <visual name='l_foot_visual'>
        <pose frame=''>0.042842 0.0701 -0.647743 -1.56405 -0 1.5708</pose>
        <geometry>
          <mesh>
            <scale>0.001 0.001 0.001</scale>
            <uri>model://heicub/meshes/sim_sea_l_sole_prt.dae</uri>
          </mesh>
        </geometry>
      </visual>
    </link>
    <joint name='l_foot_ft_sensor' type='revolute'>
      <child>l_foot</child>
      <parent>l_ankle_2</parent>
      <axis>
        <limit>
          <lower>0</lower>
          <upper>0</upper>
        </limit>
        <dynamics>
          <damping>0</damping>
          <friction>0</friction>
          <spring_reference>0</spring_reference>
          <spring_stiffness>0</spring_stiffness>
        </dynamics>
        <use_parent_model_frame>1</use_parent_model_frame>
        <xyz>0 0 1</xyz>
      </axis>
      <physics>
        <ode>
          <limit>
            <cfm>0</cfm>
            <erp>0.2</erp>
          </limit>
        </ode>
      </physics>
      <sensor name='l_foot_ft_sensor' type='force_torque'>
        <always_on>1</always_on>
        <update_rate>100</update_rate>
        <force_torque>
          <frame>child</frame>
          <measure_direction>child_to_parent</measure_direction>
        </force_torque>
        <pose>0 0 0 0 0 0</pose>
        <plugin name='left_foot_ft_plugin' filename='libgazebo_yarp_forcetorque.so'>
          <yarpConfigurationFile>model://heicub/conf/FT/gazebo_iCubHeidelberg01_left_foot_ft.ini</yarpConfigurationFile>
        </plugin>
      </sensor>
    </joint>
    <link name='r_hip_1'>
      <pose frame=''>0.006452 0.0111 -0.119913 1.5708 0 -1.5708</pose>
      <inertial>
        <pose frame=''>-0.052968 -4e-05 -0.000539 0 -0 0</pose>
        <mass>0.9279</mass>
        <inertia>
          <ixx>0.000403391</ixx>
          <ixy>-1.44877e-06</ixy>
          <ixz>2.87683e-06</ixz>
          <iyy>0.000572457</iyy>
          <iyz>-1.70772e-07</iyz>
          <izz>0.00057759</izz>
        </inertia>
      </inertial>
      <collision name='r_hip_1_collision'>
        <pose frame=''>0.0111 0.151913 0.042852 0 -0 0</pose>
        <geometry>
          <mesh>
            <scale>0.001 0.001 0.001</scale>
            <uri>model://heicub/meshes/sim_sea_r_hip_1_prt.dae</uri>
          </mesh>
        </geometry>
      </collision>
      <visual name='r_hip_1_visual'>
        <pose frame=''>0.0111 0.151913 0.042852 0 -0 0</pose>
        <geometry>
          <mesh>
            <scale>0.001 0.001 0.001</scale>
            <uri>model://heicub/meshes/sim_sea_r_hip_1_prt.dae</uri>
          </mesh>
        </geometry>
      </visual>
    </link>
    <joint name='r_hip_pitch' type='revolute'>
      <child>r_hip_1</child>
      <parent>root_link</parent>
      <axis>
        <xyz>-0 1 0</xyz>
        <limit>
          <lower>-0.57</lower>
          <upper>1.74</upper>
          <effort>50000</effort>
          <velocity>50000</velocity>
        </limit>
        <dynamics>
          <damping>0.223</damping>
          <friction>0</friction>
          <spring_reference>0</spring_reference>
          <spring_stiffness>0</spring_stiffness>
        </dynamics>
        <use_parent_model_frame>1</use_parent_model_frame>
      </axis>
    </joint>
    <link name='r_hip_2'>
      <pose frame=''>0.032814 0.0701 -0.119913 1.5708 0 -1.5708</pose>
      <inertial>
        <pose frame=''>4e-06 -0.044278 0.024983 0 -0 0</pose>
        <mass>0.4184</mass>
        <inertia>
          <ixx>0.000487899</ixx>
          <ixy>-2.35279e-07</ixy>
          <ixz>1.93211e-07</ixz>
          <iyy>0.000286147</iyy>
          <iyz>1.23695e-05</iyz>
          <izz>0.000315134</izz>
        </inertia>
      </inertial>
      <collision name='r_hip_2_collision'>
        <pose frame=''>0.0701 0.151913 0.069214 0 -0 0</pose>
        <geometry>
          <mesh>
            <scale>0.001 0.001 0.001</scale>
            <uri>model://heicub/meshes/sim_sea_r_hip_2_prt.dae</uri>
          </mesh>
        </geometry>
      </collision>
      <visual name='r_hip_2_visual'>
        <pose frame=''>0.0701 0.151913 0.069214 0 -0 0</pose>
        <geometry>
          <mesh>
            <scale>0.001 0.001 0.001</scale>
            <uri>model://heicub/meshes/sim_sea_r_hip_2_prt.dae</uri>
          </mesh>
        </geometry>
      </visual>
    </link>
    <joint name='r_hip_roll' type='revolute'>
      <child>r_hip_2</child>
      <parent>r_hip_1</parent>
      <axis>
        <xyz>1 0 -0</xyz>
        <limit>
          <lower>-0.33</lower>
          <upper>1.5708</upper>
          <effort>50000</effort>
          <velocity>50000</velocity>
        </limit>
        <dynamics>
          <damping>0.223</damping>
          <friction>0</friction>
          <spring_reference>0</spring_reference>
          <spring_stiffness>0</spring_stiffness>
        </dynamics>
        <use_parent_model_frame>1</use_parent_model_frame>
      </axis>
    </joint>
    <link name='r_hip_3'>
      <pose frame=''>0.007309 0.0701 -0.194213 3.14159 -0 -3.14159</pose>
      <inertial>
        <pose frame=''>-0.000123 -0.000282 0.008718 0 -0 0</pose>
        <mass>0.1262</mass>
        <inertia>
          <ixx>3.33523e-05</ixx>
          <ixy>4.04554e-08</ixy>
          <ixz>8.80407e-08</ixz>
          <iyy>3.34665e-05</iyy>
          <iyz>7.47286e-08</iyz>
          <izz>5.70757e-05</izz>
        </inertia>
      </inertial>
      <collision name='r_hip_3_collision'>
        <pose frame=''>0.043709 -0.0701 -0.226213 -1.5708 -0 -1.5708</pose>
        <geometry>
          <mesh>
            <scale>0.001 0.001 0.001</scale>
            <uri>model://heicub/meshes/sim_sea_r_upper_thigh_prt.dae</uri>
          </mesh>
        </geometry>
      </collision>
      <visual name='r_hip_3_visual'>
        <pose frame=''>0.043709 -0.0701 -0.226213 -1.5708 -0 -1.5708</pose>
        <geometry>
          <mesh>
            <scale>0.001 0.001 0.001</scale>
            <uri>model://heicub/meshes/sim_sea_r_upper_thigh_prt.dae</uri>
          </mesh>
        </geometry>
      </visual>
    </link>
    <joint name='r_leg_ft_sensor' type='revolute'>
      <child>r_hip_3</child>
      <parent>r_hip_2</parent>
      <axis>
        <limit>
          <lower>0</lower>
          <upper>0</upper>
        </limit>
        <dynamics>
          <damping>0</damping>
          <friction>0</friction>
          <spring_reference>0</spring_reference>
          <spring_stiffness>0</spring_stiffness>
        </dynamics>
        <use_parent_model_frame>1</use_parent_model_frame>
        <xyz>0 0 1</xyz>
      </axis>
      <physics>
        <ode>
          <limit>
            <cfm>0</cfm>
            <erp>0.2</erp>
          </limit>
        </ode>
      </physics>
      <sensor name='r_leg_ft_sensor' type='force_torque'>
        <always_on>1</always_on>
        <update_rate>100</update_rate>
        <force_torque>
          <frame>child</frame>
          <measure_direction>child_to_parent</measure_direction>
        </force_torque>
        <pose>0 0 0 0 0 0</pose>
        <plugin name='right_leg_ft_plugin' filename='libgazebo_yarp_forcetorque.so'>
          <yarpConfigurationFile>model://heicub/conf/FT/gazebo_iCubHeidelberg01_right_leg_ft.ini</yarpConfigurationFile>
        </plugin>
      </sensor>
    </joint>
    <link name='r_upper_leg'>
      <pose frame=''>0.007309 0.0701 -0.212213 1.5708 0 -1.5708</pose>
      <inertial>
        <pose frame=''>-5.9e-05 -0.079146 0.003301 0 -0 0</pose>
        <mass>2.2544</mass>
        <inertia>
          <ixx>0.00794621</ixx>
          <ixy>0.000169783</ixy>
          <ixz>9.58795e-06</ixz>
          <iyy>0.00179234</iyy>
          <iyz>-0.000163445</iyz>
          <izz>0.00796958</izz>
        </inertia>
      </inertial>
      <collision name='r_upper_leg_collision'>
        <pose frame=''>0.0701 0.241013 0.043709 0 -0 0</pose>
        <geometry>
          <mesh>
            <scale>0.001 0.001 0.001</scale>
            <uri>model://heicub/meshes/sim_sea_r_thigh_prt.dae</uri>
          </mesh>
        </geometry>
      </collision>
      <visual name='r_upper_leg_visual'>
        <pose frame=''>0.0701 0.241013 0.043709 0 -0 0</pose>
        <geometry>
          <mesh>
            <scale>0.001 0.001 0.001</scale>
            <uri>model://heicub/meshes/sim_sea_r_thigh_prt.dae</uri>
          </mesh>
        </geometry>
      </visual>
    </link>
    <joint name='r_hip_yaw' type='revolute'>
      <child>r_upper_leg</child>
      <parent>r_hip_3</parent>
      <axis>
        <xyz>0 0 -1</xyz>
        <limit>
          <lower>-1.309</lower>
          <upper>1.309</upper>
          <effort>50000</effort>
          <velocity>50000</velocity>
        </limit>
        <dynamics>
          <damping>0.223</damping>
          <friction>0</friction>
          <spring_reference>0</spring_reference>
          <spring_stiffness>0</spring_stiffness>
        </dynamics>
        <use_parent_model_frame>1</use_parent_model_frame>
      </axis>
    </joint>
    <link name='r_lower_leg'>
      <pose frame=''>0.007309 0.088057 -0.357838 1.5708 0 -1.5708</pose>
      <inertial>
        <pose frame=''>0.011764 -0.083358 0.002452 0 -0 0</pose>
        <mass>1.7086</mass>
        <inertia>
          <ixx>0.00565145</ixx>
          <ixy>0.000651976</ixy>
          <ixz>1.347e-05</ixz>
          <iyy>0.00170964</iyy>
          <iyz>-0.000147573</iyz>
          <izz>0.00615412</izz>
        </inertia>
      </inertial>
      <collision name='r_lower_leg_collision'>
        <pose frame=''>0.084257 0.386638 0.043709 0 -0 0</pose>
        <geometry>
          <mesh>
            <scale>0.001 0.001 0.001</scale>
            <uri>model://heicub/meshes/sim_sea_r_shank_prt.dae</uri>
          </mesh>
        </geometry>
      </collision>
      <visual name='r_lower_leg_visual'>
        <pose frame=''>0.084257 0.386638 0.043709 0 -0 0</pose>
        <geometry>
          <mesh>
            <scale>0.001 0.001 0.001</scale>
            <uri>model://heicub/meshes/sim_sea_r_shank_prt.dae</uri>
          </mesh>
        </geometry>
      </visual>
    </link>
    <joint name='r_knee' type='revolute'>
      <child>r_lower_leg</child>
      <parent>r_upper_leg</parent>
      <axis>
        <xyz>-0 1 0</xyz>
        <limit>
          <lower>-1.74533</lower>
          <upper>0</upper>
          <effort>50000</effort>
          <velocity>50000</velocity>
        </limit>
        <dynamics>
          <damping>0.223</damping>
          <friction>0</friction>
          <spring_reference>0</spring_reference>
          <spring_stiffness>0</spring_stiffness>
        </dynamics>
        <use_parent_model_frame>1</use_parent_model_frame>
      </axis>
    </joint>
    <link name='r_ankle_1'>
      <pose frame=''>0.007309 0.1094 -0.558838 1.57077 0 -1.5708</pose>
      <inertial>
        <pose frame=''>0.034639 -4.7e-05 0.015161 0 -0 0</pose>
        <mass>0.8929</mass>
        <inertia>
          <ixx>0.000539928</ixx>
          <ixy>-6.33371e-07</ixy>
          <ixz>-3.92688e-05</ixz>
          <iyy>0.00058171</iyy>
          <iyz>1.26546e-06</iyz>
          <izz>0.000414634</izz>
        </inertia>
      </inertial>
      <collision name='r_ankle_1_collision'>
        <pose frame=''>0.1056 0.587138 0.043709 0 -0 0</pose>
        <geometry>
          <mesh>
            <scale>0.001 0.001 0.001</scale>
            <uri>model://heicub/meshes/sim_sea_r_ankle_prt.dae</uri>
          </mesh>
        </geometry>
      </collision>
      <visual name='r_ankle_1_visual'>
        <pose frame=''>0.1056 0.587138 0.043709 0 -0 0</pose>
        <geometry>
          <mesh>
            <scale>0.001 0.001 0.001</scale>
            <uri>model://heicub/meshes/sim_sea_r_ankle_prt.dae</uri>
          </mesh>
        </geometry>
      </visual>
    </link>
    <joint name='r_ankle_pitch' type='revolute'>
      <child>r_ankle_1</child>
      <parent>r_lower_leg</parent>
      <axis>
        <xyz>0 -1 -0</xyz>
        <limit>
          <lower>-0.62</lower>
          <upper>0.47</upper>
          <effort>50000</effort>
          <velocity>50000</velocity>
        </limit>
        <dynamics>
          <damping>0.223</damping>
          <friction>0</friction>
          <spring_reference>0</spring_reference>
          <spring_stiffness>0</spring_stiffness>
        </dynamics>
        <use_parent_model_frame>1</use_parent_model_frame>
      </axis>
    </joint>
    <link name='r_ankle_2'>
      <pose frame=''>-0.037254 0.0739 -0.558837 1.57077 0 -1.5708</pose>
      <inertial>
        <pose frame=''>-8e-06 -0.038202 -0.043795 0 -0 0</pose>
        <mass>0.2675</mass>
        <inertia>
          <ixx>0.000329604</ixx>
          <ixy>6.02821e-07</ixy>
          <ixz>7.59365e-08</ixz>
          <iyy>0.000253765</iyy>
          <iyz>-1.08449e-08</iyz>
          <izz>0.000148708</izz>
        </inertia>
      </inertial>
<!--
      <collision name='r_ankle_2_collision'>
        <pose frame=''>0.0701 0.587138 -0.000853 0 -0 0</pose>
        <geometry>
          <mesh>
            <scale>0.001 0.001 0.001</scale>
            <uri>model://heicub/meshes/sim_sea_r_foot_prt.dae</uri>
          </mesh>
        </geometry>
      </collision>
-->
      <visual name='r_ankle_2_visual'>
        <pose frame=''>0.0701 0.587138 -0.000853 0 -0 0</pose>
        <geometry>
          <mesh>
            <scale>0.001 0.001 0.001</scale>
            <uri>model://heicub/meshes/sim_sea_r_foot_prt.dae</uri>
          </mesh>
        </geometry>
      </visual>
    </link>
    <joint name='r_ankle_roll' type='revolute'>
      <child>r_ankle_2</child>
      <parent>r_ankle_1</parent>
      <axis>
        <xyz>1 0 -4.8e-05</xyz>
        <limit>
          <lower>-0.418</lower>
          <upper>0.418</upper>
          <effort>50000</effort>
          <velocity>50000</velocity>
        </limit>
        <dynamics>
          <damping>0.223</damping>
          <friction>0</friction>
          <spring_reference>0</spring_reference>
          <spring_stiffness>0</spring_stiffness>
        </dynamics>
        <use_parent_model_frame>1</use_parent_model_frame>
      </axis>
    </joint>
    <link name='r_foot'>
      <pose frame=''>0.010808 0.0739 -0.619139 -3.14159 -2.4e-05 -3.14159</pose>
      <inertial>
        <pose frame=''>0.033883 0.005405 -0.001154 0 -0 0</pose>
        <mass>0.3794</mass>
        <inertia>
          <ixx>0.000283689</ixx>
          <ixy>5.83552e-05</ixy>
          <ixz>7.84955e-06</ixz>
          <iyy>0.00121493</iyy>
          <iyz>-8.90111e-07</iyz>
          <izz>0.00140898</izz>
        </inertia>
      </inertial>
<!--
      <collision name='r_foot_collision'>
        <pose frame=''>0.047209 -0.0701 -0.647439 -1.5708 -0 -1.5708</pose>
        <geometry>
          <mesh>
            <scale>0.001 0.001 0.001</scale>
            <uri>model://heicub/meshes/sim_sea_r_sole_prt.dae</uri>
          </mesh>
        </geometry>
      </collision>
-->
      <collision name='r_foot_collision_simplified'>
        <pose>0.03 -0.0 -0.006 0.0 0.0 0.0</pose>
        <geometry>
          <box>
            <size>0.22 0.10 0.04</size>
          </box>
        </geometry>
        <max_contacts>4</max_contacts>
        <surface>
          <contact>
            <ode>
              <soft_erp>0.2</soft_erp>
              <soft_cfm>0</soft_cfm>
              <kp>180000</kp>
              <kd>100</kd>
              <max_vel>100</max_vel>
              <min_depth>0.0001</min_depth>
            </ode>
          </contact>
          <friction>
            <ode>
              <mu>1</mu>
              <mu2>1</mu2>
              <fdir1>0 0 0</fdir1>
              <slip1>0</slip1>
              <slip2>0</slip2>
            </ode>
          </friction>
          <bounce>
            <restitution_coefficient>0</restitution_coefficient>
            <threshold>100000</threshold>
          </bounce>
        </surface>
      </collision>
      <visual name='r_foot_visual'>
        <pose frame=''>0.047209 -0.0701 -0.647439 -1.5708 -0 -1.5708</pose>
        <geometry>
          <mesh>
            <scale>0.001 0.001 0.001</scale>
            <uri>model://heicub/meshes/sim_sea_r_sole_prt.dae</uri>
          </mesh>
        </geometry>
      </visual>
    </link>
    <joint name='r_foot_ft_sensor' type='revolute'>
      <child>r_foot</child>
      <parent>r_ankle_2</parent>
      <axis>
        <limit>
          <lower>0</lower>
          <upper>0</upper>
        </limit>
        <dynamics>
          <damping>0</damping>
          <friction>0</friction>
          <spring_reference>0</spring_reference>
          <spring_stiffness>0</spring_stiffness>
        </dynamics>
        <use_parent_model_frame>1</use_parent_model_frame>
        <xyz>0 0 1</xyz>
      </axis>
      <physics>
        <ode>
          <limit>
            <cfm>0</cfm>
            <erp>0.2</erp>
          </limit>
        </ode>
      </physics>
      <sensor name='r_foot_ft_sensor' type='force_torque'>
        <always_on>1</always_on>
        <update_rate>100</update_rate>
        <force_torque>
          <frame>child</frame>
          <measure_direction>child_to_parent</measure_direction>
        </force_torque>
        <pose>0 0 0 0 0 0</pose>
        <plugin name='right_foot_ft_plugin' filename='libgazebo_yarp_forcetorque.so'>
          <yarpConfigurationFile>model://heicub/conf/FT/gazebo_iCubHeidelberg01_right_foot_ft.ini</yarpConfigurationFile>
        </plugin>
      </sensor>
    </joint>
    <link name='torso_1'>
      <pose frame=''>0 0.0394 0 1.5708 0 -1.5708</pose>
      <inertial>
        <pose frame=''>0.039368 0.029308 0.000142 0 -0 0</pose>
        <mass>0.7112</mass>
        <inertia>
          <ixx>0.000416742</ixx>
          <ixy>-8.88072e-07</ixy>
          <ixz>1.08936e-07</ixz>
          <iyy>0.000392401</iyy>
          <iyz>5.37987e-06</iyz>
          <izz>0.000307697</izz>
        </inertia>
      </inertial>
      <collision name='torso_1_collision'>
        <pose frame=''>0.0394 0.032 0.0364 0 -0 0</pose>
        <geometry>
          <mesh>
            <scale>0.001 0.001 0.001</scale>
            <uri>model://heicub/meshes/sim_lap_belt_1_prt.dae</uri>
          </mesh>
        </geometry>
      </collision>
      <visual name='torso_1_visual'>
        <pose frame=''>0.0394 0.032 0.0364 0 -0 0</pose>
        <geometry>
          <mesh>
            <scale>0.001 0.001 0.001</scale>
            <uri>model://heicub/meshes/sim_lap_belt_1_prt.dae</uri>
          </mesh>
        </geometry>
      </visual>
    </link>
    <joint name='torso_pitch' type='revolute'>
      <child>torso_1</child>
      <parent>root_link</parent>
      <axis>
        <xyz>0 -1 -0</xyz>
        <limit>
          <lower>-0.349066</lower>
          <upper>1.22173</upper>
          <effort>50000</effort>
          <velocity>50000</velocity>
        </limit>
        <dynamics>
          <damping>0.06</damping>
          <friction>0</friction>
          <spring_reference>0</spring_reference>
          <spring_stiffness>0</spring_stiffness>
        </dynamics>
        <use_parent_model_frame>1</use_parent_model_frame>
      </axis>
    </joint>
    <link name='torso_2'>
      <pose frame=''>0.058792 0 0.032 1.5708 0 -1.5708</pose>
      <inertial>
        <pose frame=''>-0.000122 0.028746 0.058038 0 -0 0</pose>
        <mass>0.3954</mass>
        <inertia>
          <ixx>0.000620392</ixx>
          <ixy>3.75632e-07</ixy>
          <ixz>1.15418e-07</ixz>
          <iyy>0.000446223</iyy>
          <iyz>2.06978e-05</iyz>
          <izz>0.00039084</izz>
        </inertia>
      </inertial>
      <collision name='torso_2_collision'>
        <pose frame=''>0 0 0.095192 0 -0 0</pose>
        <geometry>
          <mesh>
            <scale>0.001 0.001 0.001</scale>
            <uri>model://heicub/meshes/sim_lap_belt_2_prt.dae</uri>
          </mesh>
        </geometry>
      </collision>
      <visual name='torso_2_visual'>
        <pose frame=''>0 0 0.095192 0 -0 0</pose>
        <geometry>
          <mesh>
            <scale>0.001 0.001 0.001</scale>
            <uri>model://heicub/meshes/sim_lap_belt_2_prt.dae</uri>
          </mesh>
        </geometry>
      </visual>
    </link>
    <joint name='torso_roll' type='revolute'>
      <child>torso_2</child>
      <parent>torso_1</parent>
      <axis>
        <xyz>1 0 -0</xyz>
        <limit>
          <lower>-0.523599</lower>
          <upper>0.523599</upper>
          <effort>50000</effort>
          <velocity>50000</velocity>
        </limit>
        <dynamics>
          <damping>0.06</damping>
          <friction>0</friction>
          <spring_reference>0</spring_reference>
          <spring_stiffness>0</spring_stiffness>
        </dynamics>
        <use_parent_model_frame>1</use_parent_model_frame>
      </axis>
    </joint>
    <link name='chest'>
      <pose frame=''>-0.0055 0 0.0835 1.5708 0 -1.5708</pose>
      <inertial>
        <pose frame=''>-0.00028 0.099863 -0.005649 0 -0 0</pose>
        <mass>6.1306</mass>
        <inertia>
          <ixx>0.0252769</ixx>
          <ixy>1.73516e-05</ixy>
          <ixz>-0.0001136</ixz>
          <iyy>0.0497471</iyy>
          <iyz>0.000340001</iyz>
          <izz>0.0580977</izz>
        </inertia>
      </inertial>
      <collision name='chest_collision'>
        <pose frame=''>0 -0.052 0.0309 0 -0 0</pose>
        <geometry>
          <mesh>
            <scale>0.001 0.001 0.001</scale>
            <uri>model://heicub/meshes/sim_chest__prt.dae</uri>
          </mesh>
        </geometry>
        <surface>
          <contact>
            <ode/>
          </contact>
          <friction>
            <ode/>
          </friction>
        </surface>
      </collision>
      <visual name='chest_visual'>
        <pose frame=''>0 -0.052 0.0309 0 -0 0</pose>
        <geometry>
          <mesh>
            <scale>0.001 0.001 0.001</scale>
            <uri>model://heicub/meshes/sim_chest__prt.dae</uri>
          </mesh>
        </geometry>
        <material>
          <script>
            <uri>__default__</uri>
            <name>__default__</name>
          </script>
        </material>
      </visual>
      <gravity>1</gravity>
      <velocity_decay/>
      <self_collide>0</self_collide>
      <sensor name='imu_frame' type='imu'>
        <always_on>1</always_on>
        <update_rate>100</update_rate>
        <plugin name='iCub_yarp_gazebo_plugin_IMU' filename='libgazebo_yarp_imu.so'>
          <yarpConfigurationFile>model://heicub/conf/gazebo_iCubHeidelberg01_inertial.ini</yarpConfigurationFile>
        </plugin>
        <pose frame=''>-0.017 0.1005 -0.0381 3.14159 -0 0</pose>
      </sensor>

      <!-- Camera sensors with libgazebo_yarp_camera plugin -->
      <sensor name="left_camera" type="camera">
        <pose>0.0345 0.1 0.079 -1.5708 -1.5708 0</pose>
        <camera>
          <horizontal_fov>1.5708</horizontal_fov>
          <image>
            <width>320</width>
            <height>240</height>
          </image>
          <clip>
            <near>0.1</near>
            <far>100</far>
          </clip>
        </camera>
        <always_on>1</always_on>
        <update_rate>30</update_rate>
        <visualize>true</visualize>
        <plugin filename="libgazebo_yarp_camera.so" name="left_camera_plugin">
          <yarpConfigurationFile>model://heicub/conf/left_camera.ini</yarpConfigurationFile>
        </plugin>
      </sensor>
      <sensor name="right_camera" type="camera">
        <pose>-0.0345 0.1 0.079 -1.5708 -1.5708 0</pose>
        <camera>
          <horizontal_fov>1.5708</horizontal_fov>
          <image>
            <width>320</width>
            <height>240</height>
          </image>
          <clip>
            <near>0.1</near>
            <far>100</far>
          </clip>
        </camera>
        <always_on>1</always_on>
        <update_rate>30</update_rate>
        <visualize>true</visualize>
        <plugin filename="libgazebo_yarp_camera.so" name="right_camera_plugin">
          <yarpConfigurationFile>model://heicub/conf/right_camera.ini</yarpConfigurationFile>
        </plugin>
      </sensor>


    </link>
    <joint name='torso_yaw' type='revolute'>
      <child>chest</child>
      <parent>torso_2</parent>
      <axis>
        <xyz>-0 0 -1</xyz>
        <limit>
          <lower>-0.872665</lower>
          <upper>0.872665</upper>
          <effort>50000</effort>
          <velocity>50000</velocity>
        </limit>
        <dynamics>
          <damping>0.06</damping>
          <friction>0</friction>
          <spring_reference>0</spring_reference>
          <spring_stiffness>0</spring_stiffness>
        </dynamics>
        <use_parent_model_frame>1</use_parent_model_frame>
      </axis>
    </joint>
    <static>0</static>
    <plugin name='controlboard_torso' filename='libgazebo_yarp_controlboard.so'>
      <yarpConfigurationFile>model://heicub/conf/gazebo_iCubHeidelberg01_torso.ini</yarpConfigurationFile>
    </plugin>
    <plugin name='controlboard_right_leg' filename='libgazebo_yarp_controlboard.so'>
      <yarpConfigurationFile>model://heicub/conf/gazebo_iCubHeidelberg01_right_leg.ini</yarpConfigurationFile>
    </plugin>
    <plugin name='controlboard_left_leg' filename='libgazebo_yarp_controlboard.so'>
      <yarpConfigurationFile>model://heicub/conf/gazebo_iCubHeidelberg01_left_leg.ini</yarpConfigurationFile>
    </plugin>
    <plugin name='apply_external_wrench' filename='libgazebo_yarp_externalwrench.so'>
      <robotNamefromConfigFile>model://heicub/conf/gazebo_iCubHeidelberg01_robotname.ini</robotNamefromConfigFile>
    </plugin>
    <pose>0 0 0.635 0 -0 3.1415</pose>
  </model>
</sdf>
